Traceback (most recent call last):
  File "/opt/homebrew/anaconda3/lib/python3.11/site-packages/jupyter_cache/executors/utils.py", line 58, in single_nb_execution
    executenb(
  File "/opt/homebrew/anaconda3/lib/python3.11/site-packages/nbclient/client.py", line 1305, in execute
    return NotebookClient(nb=nb, resources=resources, km=km, **kwargs).execute()
           ^^^^^^^^^^^^^^^^^^^^^^^^^^^^^^^^^^^^^^^^^^^^^^^^^^^^^^^^^^^^^^^^^^^^^
  File "/opt/homebrew/anaconda3/lib/python3.11/site-packages/jupyter_core/utils/__init__.py", line 173, in wrapped
    return loop.run_until_complete(inner)
           ^^^^^^^^^^^^^^^^^^^^^^^^^^^^^^
  File "/opt/homebrew/anaconda3/lib/python3.11/asyncio/base_events.py", line 653, in run_until_complete
    return future.result()
           ^^^^^^^^^^^^^^^
  File "/opt/homebrew/anaconda3/lib/python3.11/site-packages/nbclient/client.py", line 705, in async_execute
    await self.async_execute_cell(
  File "/opt/homebrew/anaconda3/lib/python3.11/site-packages/nbclient/client.py", line 1058, in async_execute_cell
    await self._check_raise_for_error(cell, cell_index, exec_reply)
  File "/opt/homebrew/anaconda3/lib/python3.11/site-packages/nbclient/client.py", line 914, in _check_raise_for_error
    raise CellExecutionError.from_cell_and_msg(cell, exec_reply_content)
nbclient.exceptions.CellExecutionError: An error occurred while executing the following cell:
------------------
# np.append: 행렬 끝에 값을 덧붙임 (리스트의 append를 생각하면 됨)

a = np.array([1, 2, 3])
b = np.array([[4, 5, 6], [7, 8, 9]])

print(np.append(a, b)) # 축을 지정하지 않으면 flatten을 한다.
print(np.append(a, b, axis=0)) # 에러 발생 -> 어떻게 수정해야 할까?
------------------

----- stdout -----
[1 2 3 4 5 6 7 8 9]
------------------

[0;31m---------------------------------------------------------------------------[0m
[0;31mValueError[0m                                Traceback (most recent call last)
Cell [0;32mIn[30], line 7[0m
[1;32m      4[0m b [38;5;241m=[39m np[38;5;241m.[39marray([[[38;5;241m4[39m, [38;5;241m5[39m, [38;5;241m6[39m], [[38;5;241m7[39m, [38;5;241m8[39m, [38;5;241m9[39m]])
[1;32m      6[0m [38;5;28mprint[39m(np[38;5;241m.[39mappend(a, b)) [38;5;66;03m# 축을 지정하지 않으면 flatten을 한다.[39;00m
[0;32m----> 7[0m [38;5;28mprint[39m(np[38;5;241m.[39mappend(a, b, axis[38;5;241m=[39m[38;5;241m0[39m))

File [0;32m<__array_function__ internals>:200[0m, in [0;36mappend[0;34m(*args, **kwargs)[0m

File [0;32m/opt/homebrew/anaconda3/lib/python3.11/site-packages/numpy/lib/function_base.py:5499[0m, in [0;36mappend[0;34m(arr, values, axis)[0m
[1;32m   5497[0m     values [38;5;241m=[39m ravel(values)
[1;32m   5498[0m     axis [38;5;241m=[39m arr[38;5;241m.[39mndim[38;5;241m-[39m[38;5;241m1[39m
[0;32m-> 5499[0m [38;5;28;01mreturn[39;00m concatenate((arr, values), axis[38;5;241m=[39maxis)

File [0;32m<__array_function__ internals>:200[0m, in [0;36mconcatenate[0;34m(*args, **kwargs)[0m

[0;31mValueError[0m: all the input arrays must have same number of dimensions, but the array at index 0 has 1 dimension(s) and the array at index 1 has 2 dimension(s)

